Workbook
Name lis_act: [1]listas!$L$11:$L$30
Name lis_act: listas!$L$11:$L$30
Name lis_act2: [1]listas!$Q$11:$Q$27
Name lis_act2: listas!$Q$11:$Q$27
Name lis_dat: [1]datos!$A$10:$A$129
Name lis_dat: datos!$A$10:$A$129
Name lis_ma: listas!$B$12:$B$95
Name lis_rub: [1]listas!$J$11:$J$23
Name lis_rub: listas!$J$11:$J$23
Name ran: listas!$J$79
Name ran_act: [1]listas!$L$11:$N$30
Name ran_act: listas!$L$11:$N$30
Name ran_act2: [1]listas!$Q$11:$V$27
Name ran_act2: listas!$Q$11:$V$27
Name ran_dat: [1]datos!$A$1:$NP$300
Name ran_dat: datos!$A$1:$NP$300
Name ran_expo: #REF!
Name ran_idma: [1]listas!$C$12:$D$143
Name ran_idma: listas!$C$12:$D$143
Name ran_impo: #REF!
Name ran_ma: [1]listas!$B$12:$G$143
Name ran_ma: listas!$B$12:$G$143

Sheet Guia
G1: Datos de…
B2: Bases de Datos | G2: 45778 | H2: 45809 | I2: 45839 | J2: 45870 | K2: 45901 | L2: 45931 | M2: 45962 | N2: 45992 | O2: 46023 | P2: 46054 | Q2: 46082 | R2: 46113 | S2: 46143 | T2: 46174 | U2: 46204 | V2: 46235 | W2: 46266
A3: https://x.com/DatosAlfa | B3: 0 Precios MCBA | C3: https://www.mercadocentral.gob.ar/informaci%C3%B3n/precios-mayoristas | D3: Excel para obtener los precios promedios mensuales de hortalizas y frutas | Z3: 45992 | AA3: 46023 | AB3: 46054 | AC3: 46082 | AD3: 46113 | AE3: 46143 | AF3: 46174 | AG3: 46204
B4: Precios Pollo | C4: https://www.catedraavicola.com.ar/cotizaciones/ | D4: Excel para obtener los precios promedios mensuales de huevos y pollo | Y4: Algodón
B5: CONI_comercio_exterior | C5: https://comex.indec.gob.ar/#/database | D5: Excel para obtener datos de exportacion e importacion | Y5: Arroz
Y6: Aves
B7: Variables Macro | D7: Fuente | E7: Link | F7: Tipo de dato | Y7: Bovinos
B8: Dólar BNA | D8: Banco Nacion | E8: https://www.bna.com.ar/Personas | F8: Promedio mensual compra-venta | Y8: Cítricos Dulces
B9: Inflacion | D9: INDEC | E9: https://www.indec.gob.ar/indec/web/Nivel4-Tema-3-5-31 | F9: Indice IPC | Y9: Forestal
B10: Salario Peon Rural | D10: CNTA | E10: http://trabajoagrarioweb.trabajo.gob.ar/Consultas/Consulta.asp | F10: Salario mensual | Y10: Granos
B11: Insumos | Y11: Hortalizas
B12: Precio Gasoil | D12: Margenes | E12: https://www.margenes.com/ | F12: Precio de 100 lt de gasoil en dolares | Y12: Leche | Z12: 3
B13: Urea | D13: Margenes | E13: https://www.margenes.com/ | F13: Precio Urea Granulada por tonelada en dolares | Y13: Mandioca | Z13: Denis
B14: Glifosato | D14: Margenes | E14: https://www.margenes.com/ | F14: Precio Glifosato 54% por litro en dolares | Y14: Maní | Z14: Gaich
B15: Flete | D15: Margenes | E15: https://www.margenes.com/ | F15: Precio por flete de 300 km por tonelada de grano en dolares | Y15: Miel
Y16: Ovino
B17: Precio al Productor | D17: Fuente | E17: Link | F17: Tipo de dato | Y17: Papa | Z17: Mario
B18: Algodón | C18: C 1/2 | D18: SAGyP | E18: https://www.magyp.gob.ar/sitio/areas/ss_mercados_agropecuarios/areas/regionales/index.php | F18: Precio promedio mensual al mercado interno. Grado C 1/2 | Y18: Peras y Manzanas | Z18: Riskin, secretario de fruticultuta RN
C19: D 1/2 | D19: SAGyP | E19: https://www.magyp.gob.ar/sitio/areas/ss_mercados_agropecuarios/areas/regionales/index.php | F19: Precio promedio mensual al mercado interno. Grado D 1/2 | Y19: Porcinos
B20: Arroz | D20: SAGyP | E20: https://www.magyp.gob.ar/sitio/areas/ss_mercados_agropecuarios/areas/regionales/index.php | F20: Precio de arroz cascara Largo Fino | Y20: Tabaco
B21: Granos | C21: Cebada | D21: BCBB | E21: https://www.bcp.org.ar/cotizaciones.asp | F21: Precio promedio en puerto de Bahia Blanca | Y21: Vino y Mosto
C22: Girasol | D22: BCR | E22: https://www.cac.bcr.com.ar/es/precios-de-pizarra/consultas | F22: Precio pizarra promedio mensual | Y22: Yerba Mate | Z22: Denis
C23: Maíz | D23: Matba Rofex | E23: https://cem.matbarofex.com.ar/ | F23: Precio promedio mensual - MAI Dolar MATBA.Cuando arranque la siembra tomar Posicion de ABRIL de la campaña. Mientras tanto Tomar futuro del mes mas cercano
C24: Soja | D24: Matba Rofex | E24: https://cem.matbarofex.com.ar/ | F24: Precio promedio mensual - SOJ Dolar MATBA.Cuando arranque la siembra tomar Posicion de MAYO de la campaña. Mientras tanto Tomar futuro del mes mas cercano
C25: Sorgo | D25: SAGyP | E25: https://dinem.magyp.gob.ar/dinem_fob.WP_ConsProdf.aspx | F25: Precio mensual. Sorgo granífero, Los Demás, A granel con hasta un 15 % embolsado
C26: Trigo | D26: Matba Rofex | E26: https://cem.matbarofex.com.ar/ | F26: Precio promedio mensual - TRI Dolar MATBA.Cuando arranque la siembra tomar Posicion de ENERO de la campaña. Mientras tanto Tomar futuro del mes mas cercano
B27: Mani | D27: BCCBA | E27: https://bccba.org.ar/ | F27: Precio pizarra disponible Mani Runner
B28: Yerba Mate | C28: Hoja Verde | D28: PARTICULAR | E28: - | F28: Precio promedio mensual entre Coop y Sector Privado
C29: Canchada | D29: PARTICULAR | E29: - | F29: Precio promedio mensual entre Coop y Sector Privado
B30: Vino | C30: Tinto | D30: BCM | E30: https://bolsamza.com.ar/estadisticas-de-uvas-del-mercado-vitivinicola/ | F30: Precio promedio gral. variedad TINTO
C31: Blanco | D31: BCM | E31: https://bolsamza.com.ar/estadisticas-de-uvas-del-mercado-vitivinicola/ | F31: Precio promedio gral. variedad BLANCO
C32: Rosado | D32: BCM | E32: https://bolsamza.com.ar/estadisticas-de-uvas-del-mercado-vitivinicola/ | F32: Precio promedio gral. variedad ROSADO
B33: Mosto | D33: BCM | E33: https://bolsamza.com.ar/estadisticas-de-uvas-del-mercado-vitivinicola/ | F33: Precio promedio mosto SULFITADO
B34: Manzanas | D34: MCBA | E34: https://www.mercadocentral.gob.ar/informaci%C3%B3n/precios-mayoristas | F34: Precio promedio tipo RED DELICIUS. (MO - Modal)
B35: Peras | D35: MCBA | E35: https://www.mercadocentral.gob.ar/informaci%C3%B3n/precios-mayoristas | F35: Precio promedio especial. (MO - Modal)
B36: Limon | D36: MCBA | E36: https://www.mercadocentral.gob.ar/informaci%C3%B3n/precios-mayoristas | F36: Precio Eureka. (MO - Modal)
B37: Citricos Dulces | C37: Mandarina | D37: MCBA | E37: https://www.mercadocentral.gob.ar/informaci%C3%B3n/precios-mayoristas | F37: Precio promedio especial. (MO - Modal)
C38: Naranja | D38: MCBA | E38: https://www.mercadocentral.gob.ar/informaci%C3%B3n/precios-mayoristas | F38: Precio tipo Valencia. (MO - Modal)
C39: Pomelo | D39: MCBA | E39: https://www.mercadocentral.gob.ar/informaci%C3%B3n/precios-mayoristas | F39: Precio promedio especial. (MO - Modal)
B40: Hortalizas | C40: Papa | D40: MCBA | E40: https://www.mercadocentral.gob.ar/informaci%C3%B3n/precios-mayoristas | F40: Precio promedio tipo SPUNTA. (MO - Modal)
...

Sheet Comex
A1: Ene -Ago | B1: Expo | AG1: Impo | BM1: =A1 -> Ene -Ago | BN1: Expo | CG1: total | CH1: total s/ granos | CI1: Impo | DB1: total | DC1: total s/ granos | DE1: EXPORTACIONES GRAFICO | DX1: IMPORTACIONES GRAFICO
B2: Algodón | C2: Arroz | D2: Cebada | E2: Girasol | F2: Maíz | G2: Maní | H2: Soja | I2: Sorgo | J2: Trigo | K2: Papa | L2: Mandioca | M2: Cebolla | N2: Tomate | O2: Zanahoria | P2: Zapallo | Q2: Vitícola | R2: Manzana | S2: Pera | T2: Limón | U2: Mandarina | V2: Naranja | W2: Pomelo | X2: Forestal | Y2: Tabaco | Z2: Yerba Mate | AA2: Apícola | AB2: Aviar | AC2: Bovinos | AD2: Lechería | AE2: Ovinos | AF2: Porcinos | AG2: Algodón | AH2: Arroz | AI2: Cebada | AJ2: Girasol | AK2: Maíz | AL2: Maní | AM2: Soja | AN2: Sorgo | AO2: Trigo | AP2: Papa | AQ2: Mandioca | AR2: Cebolla | AS2: Tomate | AT2: Zanahoria | AU2: Zapallo | AV2: Vitícola | AW2: Manzana | AX2: Pera | AY2: Limón | AZ2: Mandarina | BA2: Naranja | BB2: Pomelo | BC2: Forestal | BD2: Tabaco | BE2: Yerba Mate | BF2: Apícola | BG2: Aviar | BH2: Bovinos | BI2: Lechería | BJ2: Ovinos | BK2: Porcinos | BN2: Algodón | BO2: Arroz | BP2: Granos | BQ2: Mani | BR2: Papa | BS2: Mandioca | BT2: Hortalizas | BU2: Vitivinicola | BV2: Peras y Manzanas | BW2: Citricos Dulces | BX2: Forestal | BY2: Tabaco | BZ2: Yerba Mate | CA2: Apícola | CB2: Aviar | CC2: Bovinos | CD2: Lechería | CE2: Ovinos | CF2: Porcinos | CI2: Algodón | CJ2: Arroz | CK2: Granos | CL2: Mani | CM2: Papa | CN2: Mandioca | CO2: Hortalizas | CP2: Vitivinicola | CQ2: Peras y Manzanas | CR2: Citricos Dulces | CS2: Forestal | CT2: Tabaco | CU2: Yerba Mate | CV2: Apícola | CW2: Aviar | CX2: Bovinos | CY2: Lechería | CZ2: Ovinos | DA2: Porcinos | DE2: Bovinos | DF2: Lechería | DG2: Aviar | DH2: Ovinos | DI2: Porcinos | DJ2: Vitivinicola | DK2: Yerba Mate | DL2: Algodón | DM2: Peras y Manzanas | DN2: Citricos Dulces | DO2: Forestal | DP2: Tabaco | DQ2: Apícola | DR2: Arroz | DS2: Mani | DT2: Papa | DU2: Hortalizas | DV2: Mandioca | DX2: Bovinos | DY2: Lechería | DZ2: Aviar | EA2: Ovinos | EB2: Porcinos | EC2: Vitivinicola | ED2: Yerba Mate | EE2: Algodón | EF2: Peras y Manzanas | EG2: Citricos Dulces | EH2: Forestal | EI2: Tabaco | EJ2: Apícola | EK2: Arroz | EL2: Mani | EM2: Papa | EN2: Hortalizas | EO2: Mandioca
A3: 2016 | B3: =SUM(datos!JF10:JF17) -> 54.409827 | C3: =SUM(datos!JG10:JG17) -> 149.46794 | D3: =SUM(datos!JH10:JH17) -> 640.51608 | E3: =SUM(datos!JI10:JI17) -> 626.62949 | F3: =SUM(datos!JJ10:JJ17) -> 3033.8296 | G3: =SUM(datos!JK10:JK17) -> 604.07055 | H3: =SUM(datos!JL10:JL17) -> 12368.025 | I3: =SUM(datos!JM10:JM17) -> 57.116446 | ... BK3: =SUM(datos!LO10:LO17) -> 44.470737 | BM3: 2016 | BN3: =B3 -> 54.409827 | BO3: =C3 -> 149.46794 | BP3: =SUM(D3:F3,H3:J3) -> 18209.237 | BQ3: =G3 -> 604.07055 | BR3: =K3 -> 145.68574 | BS3: =L3 -> 0 | BT3: =SUM(M3:P3) -> 28.489358 | BU3: =Q3 -> 648.49007 | BV3: =SUM(R3:S3) -> 341.38826 | BW3: =SUM(T3:W3) -> 513.85055 | BX3: =X3 -> 129.4643 | BY3: =Y3 -> 232.85714 | BZ3: =Z3 -> 42.311108 | CA3: =AA3 -> 123.20439 | CB3: =AB3 -> 179.52155 | CC3: =AC3 -> 1287.3146 | CD3: =AD3 -> 387.09514 | CE3: =AE3 -> 156.29588 | CF3: =AF3 -> 7.0322254 | CG3: =SUM(BN3:CF3) -> 23240.186 | CH3: =CG3-BP3 -> 5030.9486 | CI3: =AG3 -> 86.194496 | CJ3: =AH3 -> 4.0060256 | CK3: =SUM(AI3:AK3,AM3:AO3) -> 245.28067 | CL3: =AL3 -> 0.12216077 | CM3: =AP3 -> 17.887523 | CN3: =AQ3 -> 0.83185262 | CO3: =SUM(AR3:AU3) -> 27.856347 | CP3: =AV3 -> 2.7151343 | CQ3: =SUM(AW3:AX3) -> 4.4321264 | CR3: =SUM(AY3:BB3) -> 9.8060333 | CS3: =BC3 -> 154.22261 | CT3: =BD3 -> 34.735092 | CU3: =BE3 -> 0.50848095 | CV3: =BF3 -> 0.01478013 | CW3: =BG3 -> 28.210152 | CX3: =BH3 -> 29.801982 | CY3: =BI3 -> 9.2453238 | CZ3: =BJ3 -> 5.3927472 | DA3: =BK3 -> 44.470737 | DB3: =SUM(CI3:DA3) -> 705.73428 | DC3: =DB3-CK3 -> 460.45361 | DD3: 2016 | DE3: =CC3 -> 1287.3146 | DF3: =CD3 -> 387.09514 | DG3: =CB3 -> 179.52155 | DH3: =CE3 -> 156.29588 | DI3: =CF3 -> 7.0322254 | DJ3: =BU3 -> 648.49007 | DK3: =BZ3 -> 42.311108 | DL3: =BN3 -> 54.409827 | DM3: =BV3 -> 341.38826 | DN3: =BW3 -> 513.85055 | DO3: =BX3 -> 129.4643 | DP3: =BY3 -> 232.85714 | DQ3: =CA3 -> 123.20439 | DR3: =BO3 -> 149.46794 | DS3: =BQ3 -> 604.07055 | DT3: =BR3 -> 145.68574 | DU3: =BT3 -> 28.489358 | DV3: =BS3 -> 0 | DX3: =CX3 -> 29.801982 | DY3: =CY3 -> 9.2453238 | DZ3: =CW3 -> 28.210152 | EA3: =CZ3 -> 5.3927472 | EB3: =DA3 -> 44.470737 | EC3: =CP3 -> 2.7151343 | ED3: =CU3 -> 0.50848095 | EE3: =CI3 -> 86.194496 | EF3: =CQ3 -> 4.4321264 | EG3: =CR3 -> 9.8060333 | EH3: =CS3 -> 154.22261 | EI3: =CT3 -> 34.735092 | EJ3: =CV3 -> 0.01478013 | EK3: =CJ3 -> 4.0060256 | EL3: =CL3 -> 0.12216077 | EM3: =CM3 -> 17.887523 | EN3: =CO3 -> 27.856347 | EO3: =CN3 -> 0.83185262
A4: 2017 | B4: =SUM(datos!JF22:JF29) -> 49.565386 | C4: =SUM(datos!JG22:JG29) -> 126.87513 | D4: =SUM(datos!JH22:JH29) -> 523.9634 | E4: =SUM(datos!JI22:JI29) -> 571.33697 | F4: =SUM(datos!JJ22:JJ29) -> 2727.6092 | G4: =SUM(datos!JK22:JK29) -> 560.18411 | H4: =SUM(datos!JL22:JL29) -> 11308.755 | I4: =SUM(datos!JM22:JM29) -> 43.107363 | ... BK4: =SUM(datos!LO22:LO29) -> 80.561475 | BM4: 2017 | BN4: =B4 -> 49.565386 | BO4: =C4 -> 126.87513 | BP4: =SUM(D4:F4,H4:J4) -> 16925.388 | BQ4: =G4 -> 560.18411 | BR4: =K4 -> 125.01639 | BS4: =L4 -> 0.001664 | BT4: =SUM(M4:P4) -> 16.598591 | BU4: =Q4 -> 614.54182 | BV4: =SUM(R4:S4) -> 328.57696 | BW4: =SUM(T4:W4) -> 415.40884 | BX4: =X4 -> 158.43166 | BY4: =Y4 -> 214.27715 | BZ4: =Z4 -> 55.553768 | CA4: =AA4 -> 134.11465 | CB4: =AB4 -> 213.07472 | CC4: =AC4 -> 1475.5046 | CD4: =AD4 -> 357.27884 | CE4: =AE4 -> 144.58608 | CF4: =AF4 -> 12.538792 | CG4: =SUM(BN4:CF4) -> 21927.517 | CH4: =CG4-BP4 -> 5002.1291 | CI4: =AG4 -> 66.504423 | CJ4: =AH4 -> 3.7127877 | CK4: =SUM(AI4:AK4,AM4:AO4) -> 575.26323 | CL4: =AL4 -> 0.67187738 | CM4: =AP4 -> 23.607516 | CN4: =AQ4 -> 4.4833476 | CO4: =SUM(AR4:AU4) -> 32.063187 | CP4: =AV4 -> 50.990598 | CQ4: =SUM(AW4:AX4) -> 10.98331 | CR4: =SUM(AY4:BB4) -> 11.5585 | CS4: =BC4 -> 152.61877 | CT4: =BD4 -> 34.655634 | CU4: =BE4 -> 0.68021238 | CV4: =BF4 -> 0.22386681 | CW4: =BG4 -> 22.281796 | CX4: =BH4 -> 28.894064 | CY4: =BI4 -> 19.88767 | CZ4: =BJ4 -> 2.3918065 | DA4: =BK4 -> 80.561475 | DB4: =SUM(CI4:DA4) -> 1122.0341 | DC4: =DB4-CK4 -> 546.77084 | DD4: 2017 | DE4: =CC4 -> 1475.5046 | DF4: =CD4 -> 357.27884 | DG4: =CB4 -> 213.07472 | DH4: =CE4 -> 144.58608 | DI4: =CF4 -> 12.538792 | DJ4: =BU4 -> 614.54182 | DK4: =BZ4 -> 55.553768 | DL4: =BN4 -> 49.565386 | DM4: =BV4 -> 328.57696 | DN4: =BW4 -> 415.40884 | DO4: =BX4 -> 158.43166 | DP4: =BY4 -> 214.27715 | DQ4: =CA4 -> 134.11465 | DR4: =BO4 -> 126.87513 | DS4: =BQ4 -> 560.18411 | DT4: =BR4 -> 125.01639 | DU4: =BT4 -> 16.598591 | DV4: =BS4 -> 0.001664 | DX4: =CX4 -> 28.894064 | DY4: =CY4 -> 19.88767 | DZ4: =CW4 -> 22.281796 | EA4: =CZ4 -> 2.3918065 | EB4: =DA4 -> 80.561475 | EC4: =CP4 -> 50.990598 | ED4: =CU4 -> 0.68021238 | EE4: =CI4 -> 66.504423 | EF4: =CQ4 -> 10.98331 | EG4: =CR4 -> 11.5585 | EH4: =CS4 -> 152.61877 | EI4: =CT4 -> 34.655634 | EJ4: =CV4 -> 0.22386681 | EK4: =CJ4 -> 3.7127877 | EL4: =CL4 -> 0.67187738 | EM4: =CM4 -> 23.607516 | EN4: =CO4 -> 32.063187 | EO4: =CN4 -> 4.4833476
A5: 2018 | B5: =SUM(datos!JF34:JF41) -> 66.392231 | C5: =SUM(datos!JG34:JG41) -> 123.09376 | D5: =SUM(datos!JH34:JH41) -> 540.71463 | E5: =SUM(datos!JI34:JI41) -> 580.10943 | F5: =SUM(datos!JJ34:JJ41) -> 3130.3466 | G5: =SUM(datos!JK34:JK41) -> 463.90971 | H5: =SUM(datos!JL34:JL41) -> 9076.2721 | I5: =SUM(datos!JM34:JM41) -> 27.122047 | ... BK5: =SUM(datos!LO34:LO41) -> 76.963965 | BM5: 2018 | BN5: =B5 -> 66.392231 | BO5: =C5 -> 123.09376 | BP5: =SUM(D5:F5,H5:J5) -> 15169.646 | BQ5: =G5 -> 463.90971 | BR5: =K5 -> 112.84753 | BS5: =L5 -> 0 | BT5: =SUM(M5:P5) -> 31.018285 | BU5: =Q5 -> 638.19389 | BV5: =SUM(R5:S5) -> 361.95987 | BW5: =SUM(T5:W5) -> 433.10917 | BX5: =X5 -> 50.234011 | BY5: =Y5 -> 191.74422 | BZ5: =Z5 -> 69.072689 | CA5: =AA5 -> 125.53562 | CB5: =AB5 -> 203.3206 | CC5: =AC5 -> 1949.4436 | CD5: =AD5 -> 462.15821 | CE5: =AE5 -> 196.13031 | CF5: =AF5 -> 14.424982 | CG5: =SUM(BN5:CF5) -> 20662.235 | CH5: =CG5-BP5 -> 5492.5887 | CI5: =AG5 -> 68.738869 | CJ5: =AH5 -> 3.2527584 | CK5: =SUM(AI5:AK5,AM5:AO5) -> 1646.5089 | CL5: =AL5 -> 0.20511525 | CM5: =AP5 -> 34.349134 | CN5: =AQ5 -> 4.1272484 | CO5: =SUM(AR5:AU5) -> 25.513629 | CP5: =AV5 -> 7.0511017 | CQ5: =SUM(AW5:AX5) -> 6.5012361 | CR5: =SUM(AY5:BB5) -> 9.34071 | CS5: =BC5 -> 167.11321 | CT5: =BD5 -> 19.971598 | CU5: =BE5 -> 0.40205221 | CV5: =BF5 -> 0 | CW5: =BG5 -> 19.208996 | CX5: =BH5 -> 24.279341 | CY5: =BI5 -> 14.199746 | CZ5: =BJ5 -> 0.7725766 | DA5: =BK5 -> 76.963965 | DB5: =SUM(CI5:DA5) -> 2128.5002 | DC5: =DB5-CK5 -> 481.99129 | DD5: 2018 | DE5: =CC5 -> 1949.4436 | DF5: =CD5 -> 462.15821 | DG5: =CB5 -> 203.3206 | DH5: =CE5 -> 196.13031 | DI5: =CF5 -> 14.424982 | DJ5: =BU5 -> 638.19389 | DK5: =BZ5 -> 69.072689 | DL5: =BN5 -> 66.392231 | DM5: =BV5 -> 361.95987 | DN5: =BW5 -> 433.10917 | DO5: =BX5 -> 50.234011 | DP5: =BY5 -> 191.74422 | DQ5: =CA5 -> 125.53562 | DR5: =BO5 -> 123.09376 | DS5: =BQ5 -> 463.90971 | DT5: =BR5 -> 112.84753 | DU5: =BT5 -> 31.018285 | DV5: =BS5 -> 0 | DX5: =CX5 -> 24.279341 | DY5: =CY5 -> 14.199746 | DZ5: =CW5 -> 19.208996 | EA5: =CZ5 -> 0.7725766 | EB5: =DA5 -> 76.963965 | EC5: =CP5 -> 7.0511017 | ED5: =CU5 -> 0.40205221 | EE5: =CI5 -> 68.738869 | EF5: =CQ5 -> 6.5012361 | EG5: =CR5 -> 9.34071 | EH5: =CS5 -> 167.11321 | EI5: =CT5 -> 19.971598 | EJ5: =CV5 -> 0 | EK5: =CJ5 -> 3.2527584 | EL5: =CL5 -> 0.20511525 | EM5: =CM5 -> 34.349134 | EN5: =CO5 -> 25.513629 | EO5: =CN5 -> 4.1272484
A6: 2019 | B6: =SUM(datos!JF46:JF53) -> 77.070064 | C6: =SUM(datos!JG46:JG53) -> 109.70648 | D6: =SUM(datos!JH46:JH53) -> 740.64458 | E6: =SUM(datos!JI46:JI53) -> 735.96175 | F6: =SUM(datos!JJ46:JJ53) -> 4187.1008 | G6: =SUM(datos!JK46:JK53) -> 489.30623 | H6: =SUM(datos!JL46:JL53) -> 10207.492 | I6: =SUM(datos!JM46:JM53) -> 34.7978 | ... BK6: =SUM(datos!LO46:LO53) -> 67.506336 | BM6: 2019 | BN6: =B6 -> 77.070064 | BO6: =C6 -> 109.70648 | BP6: =SUM(D6:F6,H6:J6) -> 17848.046 | BQ6: =G6 -> 489.30623 | BR6: =K6 -> 147.41111 | BS6: =L6 -> 0 | BT6: =SUM(M6:P6) -> 39.338341 | BU6: =Q6 -> 631.23457 | BV6: =SUM(R6:S6) -> 288.84739 | BW6: =SUM(T6:W6) -> 319.7925 | BX6: =X6 -> 30.672148 | BY6: =Y6 -> 152.46961 | BZ6: =Z6 -> 58.250138 | CA6: =AA6 -> 104.95143 | CB6: =AB6 -> 272.49848 | CC6: =AC6 -> 2345.5506 | CD6: =AD6 -> 394.36482 | CE6: =AE6 -> 175.64853 | CF6: =AF6 -> 13.156129 | CG6: =SUM(BN6:CF6) -> 23498.315 | CH6: =CG6-BP6 -> 5650.2686 | CI6: =AG6 -> 51.377997 | CJ6: =AH6 -> 2.5394806 | CK6: =SUM(AI6:AK6,AM6:AO6) -> 1521.8325 | CL6: =AL6 -> 0.1844853 | CM6: =AP6 -> 14.437343 | CN6: =AQ6 -> 1.6483422 | CO6: =SUM(AR6:AU6) -> 14.380355 | CP6: =AV6 -> 5.6318893 | CQ6: =SUM(AW6:AX6) -> 3.4126421 | CR6: =SUM(AY6:BB6) -> 4.8034722 | CS6: =BC6 -> 154.6279 | CT6: =BD6 -> 34.935696 | CU6: =BE6 -> 0.74095648 | CV6: =BF6 -> 0.33565781 | CW6: =BG6 -> 18.455583 | CX6: =BH6 -> 46.287423 | CY6: =BI6 -> 18.368854 | CZ6: =BJ6 -> 0.88820652 | DA6: =BK6 -> 67.506336 | DB6: =SUM(CI6:DA6) -> 1962.3951 | DC6: =DB6-CK6 -> 440.56262 | DD6: 2019 | DE6: =CC6 -> 2345.5506 | DF6: =CD6 -> 394.36482 | DG6: =CB6 -> 272.49848 | DH6: =CE6 -> 175.64853 | DI6: =CF6 -> 13.156129 | DJ6: =BU6 -> 631.23457 | DK6: =BZ6 -> 58.250138 | DL6: =BN6 -> 77.070064 | DM6: =BV6 -> 288.84739 | DN6: =BW6 -> 319.7925 | DO6: =BX6 -> 30.672148 | DP6: =BY6 -> 152.46961 | DQ6: =CA6 -> 104.95143 | DR6: =BO6 -> 109.70648 | DS6: =BQ6 -> 489.30623 | DT6: =BR6 -> 147.41111 | DU6: =BT6 -> 39.338341 | DV6: =BS6 -> 0 | DX6: =CX6 -> 46.287423 | DY6: =CY6 -> 18.368854 | DZ6: =CW6 -> 18.455583 | EA6: =CZ6 -> 0.88820652 | EB6: =DA6 -> 67.506336 | EC6: =CP6 -> 5.6318893 | ED6: =CU6 -> 0.74095648 | EE6: =CI6 -> 51.377997 | EF6: =CQ6 -> 3.4126421 | EG6: =CR6 -> 4.8034722 | EH6: =CS6 -> 154.6279 | EI6: =CT6 -> 34.935696 | EJ6: =CV6 -> 0.33565781 | EK6: =CJ6 -> 2.5394806 | EL6: =CL6 -> 0.1844853 | EM6: =CM6 -> 14.437343 | EN6: =CO6 -> 14.380355 | EO6: =CN6 -> 1.6483422
A7: 2020 | B7: =SUM(datos!JF58:JF65) -> 78.485275 | C7: =SUM(datos!JG58:JG65) -> 132.04623 | D7: =SUM(datos!JH58:JH65) -> 713.75236 | E7: =SUM(datos!JI58:JI65) -> 940.32054 | F7: =SUM(datos!JJ58:JJ65) -> 5037.628 | G7: =SUM(datos!JK58:JK65) -> 776.62292 | H7: =SUM(datos!JL58:JL65) -> 14095.232 | I7: =SUM(datos!JM58:JM65) -> 182.12939 | ... BK7: =SUM(datos!LO58:LO65) -> 39.814807 | BM7: 2020 | BN7: =B7 -> 78.485275 | BO7: =C7 -> 132.04623 | BP7: =SUM(D7:F7,H7:J7) -> 23141.08 | BQ7: =G7 -> 776.62292 | BR7: =K7 -> 129.07161 | BS7: =L7 -> 0.0025 | BT7: =SUM(M7:P7) -> 44.521935 | BU7: =Q7 -> 630.37704 | BV7: =SUM(R7:S7) -> 325.7942 | BW7: =SUM(T7:W7) -> 364.08946 | BX7: =X7 -> 130.45437 | BY7: =Y7 -> 199.67913 | BZ7: =Z7 -> 73.211228 | CA7: =AA7 -> 145.55567 | CB7: =AB7 -> 326.81322 | CC7: =AC7 -> 2365.1168 | CD7: =AD7 -> 783.60926 | CE7: =AE7 -> 137.43048 | CF7: =AF7 -> 52.660321 | CG7: =SUM(BN7:CF7) -> 29836.621 | CH7: =CG7-BP7 -> 6695.5416 | CI7: =AG7 -> 32.559056 | CJ7: =AH7 -> 3.2971293 | CK7: =SUM(AI7:AK7,AM7:AO7) -> 1460.4608 | CL7: =AL7 -> 0.28117517 | CM7: =AP7 -> 13.71036 | CN7: =AQ7 -> 1.6076478 | CO7: =SUM(AR7:AU7) -> 28.404996 | CP7: =AV7 -> 5.1813193 | CQ7: =SUM(AW7:AX7) -> 2.5358095 | CR7: =SUM(AY7:BB7) -> 2.028996 | CS7: =BC7 -> 124.15329 | CT7: =BD7 -> 35.706773 | CU7: =BE7 -> 26.540224 | CV7: =BF7 -> 0.00861474 | CW7: =BG7 -> 18.628267 | CX7: =BH7 -> 41.053205 | CY7: =BI7 -> 7.49556 | CZ7: =BJ7 -> 1.7585355 | DA7: =BK7 -> 39.814807 | DB7: =SUM(CI7:DA7) -> 1845.2266 | DC7: =DB7-CK7 -> 384.76576 | DD7: 2020 | DE7: =CC7 -> 2365.1168 | DF7: =CD7 -> 783.60926 | DG7: =CB7 -> 326.81322 | DH7: =CE7 -> 137.43048 | DI7: =CF7 -> 52.660321 | DJ7: =BU7 -> 630.37704 | DK7: =BZ7 -> 73.211228 | DL7: =BN7 -> 78.485275 | DM7: =BV7 -> 325.7942 | DN7: =BW7 -> 364.08946 | DO7: =BX7 -> 130.45437 | DP7: =BY7 -> 199.67913 | DQ7: =CA7 -> 145.55567 | DR7: =BO7 -> 132.04623 | DS7: =BQ7 -> 776.62292 | DT7: =BR7 -> 129.07161 | DU7: =BT7 -> 44.521935 | DV7: =BS7 -> 0.0025 | DX7: =CX7 -> 41.053205 | DY7: =CY7 -> 7.49556 | DZ7: =CW7 -> 18.628267 | EA7: =CZ7 -> 1.7585355 | EB7: =DA7 -> 39.814807 | EC7: =CP7 -> 5.1813193 | ED7: =CU7 -> 26.540224 | EE7: =CI7 -> 32.559056 | EF7: =CQ7 -> 2.5358095 | EG7: =CR7 -> 2.028996 | EH7: =CS7 -> 124.15329 | EI7: =CT7 -> 35.706773 | EJ7: =CV7 -> 0.00861474 | EK7: =CJ7 -> 3.2971293 | EL7: =CL7 -> 0.28117517 | EM7: =CM7 -> 13.71036 | EN7: =CO7 -> 28.404996 | EO7: =CN7 -> 1.6076478
A8: 2021 | B8: =SUM(datos!JF70:JF77) -> 111.61179 | C8: =SUM(datos!JG70:JG77) -> 186.74919 | D8: =SUM(datos!JH70:JH77) -> 893.53495 | E8: =SUM(datos!JI70:JI77) -> 2236.1217 | F8: =SUM(datos!JJ70:JJ77) -> 6898.0969 | G8: =SUM(datos!JK70:JK77) -> 783.51957 | H8: =SUM(datos!JL70:JL77) -> 23783.826 | I8: =SUM(datos!JM70:JM77) -> 353.81834 | ... BK8: =SUM(datos!LO70:LO77) -> 67.972382 | BM8: 2021 | BN8: =B8 -> 111.61179 | BO8: =C8 -> 186.74919 | BP8: =SUM(D8:F8,H8:J8) -> 37026.775 | BQ8: =G8 -> 783.51957 | BR8: =K8 -> 184.49823 | BS8: =L8 -> 0 | BT8: =SUM(M8:P8) -> 37.52872 | BU8: =Q8 -> 655.50522 | BV8: =SUM(R8:S8) -> 316.41513 | BW8: =SUM(T8:W8) -> 311.97407 | BX8: =X8 -> 247.29755 | BY8: =Y8 -> 175.73344 | BZ8: =Z8 -> 75.825863 | CA8: =AA8 -> 185.25047 | CB8: =AB8 -> 295.41043 | CC8: =AC8 -> 2487.5807 | CD8: =AD8 -> 950.31028 | CE8: =AE8 -> 197.83466 | CF8: =AF8 -> 57.222602 | CG8: =SUM(BN8:CF8) -> 44287.043 | CH8: =CG8-BP8 -> 7260.2679 | CI8: =AG8 -> 54.607067 | CJ8: =AH8 -> 1.2123001 | CK8: =SUM(AI8:AK8,AM8:AO8) -> 2102.7844 | CL8: =AL8 -> 0.36556502 | CM8: =AP8 -> 7.1906577 | CN8: =AQ8 -> 2.275207 | CO8: =SUM(AR8:AU8) -> 15.809762 | CP8: =AV8 -> 10.011797 | CQ8: =SUM(AW8:AX8) -> 5.6128368 | CR8: =SUM(AY8:BB8) -> 12.824672 | CS8: =BC8 -> 146.769 | CT8: =BD8 -> 44.98699 | CU8: =BE8 -> 29.901723 | CV8: =BF8 -> 0.02699808 | CW8: =BG8 -> 20.862892 | CX8: =BH8 -> 50.01804 | CY8: =BI8 -> 11.386333 | CZ8: =BJ8 -> 1.9568038 | DA8: =BK8 -> 67.972382 | DB8: =SUM(CI8:DA8) -> 2586.5754 | DC8: =DB8-CK8 -> 483.79102 | DD8: 2021 | DE8: =CC8 -> 2487.5807 | DF8: =CD8 -> 950.31028 | DG8: =CB8 -> 295.41043 | DH8: =CE8 -> 197.83466 | DI8: =CF8 -> 57.222602 | DJ8: =BU8 -> 655.50522 | DK8: =BZ8 -> 75.825863 | DL8: =BN8 -> 111.61179 | DM8: =BV8 -> 316.41513 | DN8: =BW8 -> 311.97407 | DO8: =BX8 -> 247.29755 | DP8: =BY8 -> 175.73344 | DQ8: =CA8 -> 185.25047 | DR8: =BO8 -> 186.74919 | DS8: =BQ8 -> 783.51957 | DT8: =BR8 -> 184.49823 | DU8: =BT8 -> 37.52872 | DV8: =BS8 -> 0 | DX8: =CX8 -> 50.01804 | DY8: =CY8 -> 11.386333 | DZ8: =CW8 -> 20.862892 | EA8: =CZ8 -> 1.9568038 | EB8: =DA8 -> 67.972382 | EC8: =CP8 -> 10.011797 | ED8: =CU8 -> 29.901723 | EE8: =CI8 -> 54.607067 | EF8: =CQ8 -> 5.6128368 | EG8: =CR8 -> 12.824672 | EH8: =CS8 -> 146.769 | EI8: =CT8 -> 44.98699 | EJ8: =CV8 -> 0.02699808 | EK8: =CJ8 -> 1.2123001 | EL8: =CL8 -> 0.36556502 | EM8: =CM8 -> 7.1906577 | EN8: =CO8 -> 15.809762 | EO8: =CN8 -> 2.275207
A9: 2022 | B9: =SUM(datos!JF82:JF89) -> 168.89631 | C9: =SUM(datos!JG82:JG89) -> 172.08141 | D9: =SUM(datos!JH82:JH89) -> 1663.7725 | E9: =SUM(datos!JI82:JI89) -> 2565.9898 | F9: =SUM(datos!JJ82:JJ89) -> 8034.3728 | G9: =SUM(datos!JK82:JK89) -> 799.96 | H9: =SUM(datos!JL82:JL89) -> 22352.225 | I9: =SUM(datos!JM82:JM89) -> 490.58741 | ... BK9: =SUM(datos!LO82:LO89) -> 82.235693 | BM9: 2022 | BN9: =B9 -> 168.89631 | BO9: =C9 -> 172.08141 | BP9: =SUM(D9:F9,H9:J9) -> 41310.408 | BQ9: =G9 -> 799.96 | BR9: =K9 -> 204.29614 | BS9: =L9 -> 0 | BT9: =SUM(M9:P9) -> 41.92377 | BU9: =Q9 -> 703.96595 | BV9: =SUM(R9:S9) -> 247.16688 | BW9: =SUM(T9:W9) -> 267.88394 | BX9: =X9 -> 261.30502 | BY9: =Y9 -> 247.4236 | BZ9: =Z9 -> 66.943449 | CA9: =AA9 -> 211.22974 | CB9: =AB9 -> 383.06839 | CC9: =AC9 -> 3324.2569 | CD9: =AD9 -> 1244.8464 | CE9: =AE9 -> 191.35108 | CF9: =AF9 -> 10.239835 | CG9: =SUM(BN9:CF9) -> 49857.247 | CH9: =CG9-BP9 -> 8546.8388 | CI9: =AG9 -> 76.141605 | CJ9: =AH9 -> 0.51128799 | CK9: =SUM(AI9:AK9,AM9:AO9) -> 1969.2882 | CL9: =AL9 -> 0.61651101 | CM9: =AP9 -> 5.2106525 | CN9: =AQ9 -> 6.3776566 | CO9: =SUM(AR9:AU9) -> 17.916753 | CP9: =AV9 -> 11.112273 | CQ9: =SUM(AW9:AX9) -> 4.832072 | CR9: =SUM(AY9:BB9) -> 4.5914456 | CS9: =BC9 -> 177.00081 | CT9: =BD9 -> 34.229479 | CU9: =BE9 -> 26.88767 | CV9: =BF9 -> 0.08135102 | CW9: =BG9 -> 37.657641 | CX9: =BH9 -> 64.912821 | CY9: =BI9 -> 25.918449 | CZ9: =BJ9 -> 1.4838373 | DA9: =BK9 -> 82.235693 | DB9: =SUM(CI9:DA9) -> 2547.0062 | DC9: =DB9-CK9 -> 577.718 | DD9: 2022 | DE9: =CC9 -> 3324.2569 | DF9: =CD9 -> 1244.8464 | DG9: =CB9 -> 383.06839 | DH9: =CE9 -> 191.35108 | DI9: =CF9 -> 10.239835 | DJ9: =BU9 -> 703.96595 | DK9: =BZ9 -> 66.943449 | DL9: =BN9 -> 168.89631 | DM9: =BV9 -> 247.16688 | DN9: =BW9 -> 267.88394 | DO9: =BX9 -> 261.30502 | DP9: =BY9 -> 247.4236 | DQ9: =CA9 -> 211.22974 | DR9: =BO9 -> 172.08141 | DS9: =BQ9 -> 799.96 | DT9: =BR9 -> 204.29614 | DU9: =BT9 -> 41.92377 | DV9: =BS9 -> 0 | DX9: =CX9 -> 64.912821 | DY9: =CY9 -> 25.918449 | DZ9: =CW9 -> 37.657641 | EA9: =CZ9 -> 1.4838373 | EB9: =DA9 -> 82.235693 | EC9: =CP9 -> 11.112273 | ED9: =CU9 -> 26.88767 | EE9: =CI9 -> 76.141605 | EF9: =CQ9 -> 4.832072 | EG9: =CR9 -> 4.5914456 | EH9: =CS9 -> 177.00081 | EI9: =CT9 -> 34.229479 | EJ9: =CV9 -> 0.08135102 | EK9: =CJ9 -> 0.51128799 | EL9: =CL9 -> 0.61651101 | EM9: =CM9 -> 5.2106525 | EN9: =CO9 -> 17.916753 | EO9: =CN9 -> 6.3776566
A10: 2023 | B10: =SUM(datos!JF94:JF101) -> 30.558404 | C10: =SUM(datos!JG94:JG101) -> 190.79966 | D10: =SUM(datos!JH94:JH101) -> 1234.4019 | E10: =SUM(datos!JI94:JI101) -> 1386.1841 | F10: =SUM(datos!JJ94:JJ101) -> 5597.6435 | G10: =SUM(datos!JK94:JK101) -> 874.25125 | H10: =SUM(datos!JL94:JL101) -> 16037.112 | I10: =SUM(datos!JM94:JM101) -> 210.19931 | ... BK10: =SUM(datos!LO94:LO101) -> 42.658364 | BM10: 2023 | BN10: =B10 -> 30.558404 | BO10: =C10 -> 190.79966 | BP10: =SUM(D10:F10,H10:J10) -> 25410.021 | BQ10: =G10 -> 874.25125 | BR10: =K10 -> 218.73925 | BS10: =L10 -> 0 | BT10: =SUM(M10:P10) -> 46.856545 | BU10: =Q10 -> 559.61141 | BV10: =SUM(R10:S10) -> 287.54382 | BW10: =SUM(T10:W10) -> 235.95864 | BX10: =X10 -> 199.43735 | BY10: =Y10 -> 361.64912 | BZ10: =Z10 -> 70.790468 | CA10: =AA10 -> 147.42474 | CB10: =AB10 -> 231.61567 | CC10: =AC10 -> 2707.7336 | CD10: =AD10 -> 1009.2699 | CE10: =AE10 -> 145.69417 | CF10: =AF10 -> 13.396281 | CG10: =SUM(BN10:CF10) -> 32741.352 | CH10: =CG10-BP10 -> 7331.3303 | CI10: =AG10 -> 66.517924 | CJ10: =AH10 -> 0.33939125 | CK10: =SUM(AI10:AK10,AM10:AO10) -> 4288.0667 | CL10: =AL10 -> 0.46198871 | CM10: =AP10 -> 10.417919 | CN10: =AQ10 -> 8.0199833 | CO10: =SUM(AR10:AU10) -> 11.989456 | CP10: =AV10 -> 10.452242 | CQ10: =SUM(AW10:AX10) -> 5.9066646 | CR10: =SUM(AY10:BB10) -> 4.9948899 | CS10: =BC10 -> 200.04574 | CT10: =BD10 -> 49.274931 | CU10: =BE10 -> 7.3993995 | CV10: =BF10 -> 0.007038 | CW10: =BG10 -> 30.143111 | CX10: =BH10 -> 35.42977 | CY10: =BI10 -> 18.707808 | CZ10: =BJ10 -> 2.4594297 | DA10: =BK10 -> 42.658364 | DB10: =SUM(CI10:DA10) -> 4793.2928 | DC10: =DB10-CK10 -> 505.22605 | DD10: 2023 | DE10: =CC10 -> 2707.7336 | DF10: =CD10 -> 1009.2699 | DG10: =CB10 -> 231.61567 | DH10: =CE10 -> 145.69417 | DI10: =CF10 -> 13.396281 | DJ10: =BU10 -> 559.61141 | DK10: =BZ10 -> 70.790468 | DL10: =BN10 -> 30.558404 | DM10: =BV10 -> 287.54382 | DN10: =BW10 -> 235.95864 | DO10: =BX10 -> 199.43735 | DP10: =BY10 -> 361.64912 | DQ10: =CA10 -> 147.42474 | DR10: =BO10 -> 190.79966 | DS10: =BQ10 -> 874.25125 | DT10: =BR10 -> 218.73925 | DU10: =BT10 -> 46.856545 | DV10: =BS10 -> 0 | DX10: =CX10 -> 35.42977 | DY10: =CY10 -> 18.707808 | DZ10: =CW10 -> 30.143111 | EA10: =CZ10 -> 2.4594297 | EB10: =DA10 -> 42.658364 | EC10: =CP10 -> 10.452242 | ED10: =CU10 -> 7.3993995 | EE10: =CI10 -> 66.517924 | EF10: =CQ10 -> 5.9066646 | EG10: =CR10 -> 4.9948899 | EH10: =CS10 -> 200.04574 | EI10: =CT10 -> 49.274931 | EJ10: =CV10 -> 0.007038 | EK10: =CJ10 -> 0.33939125 | EL10: =CL10 -> 0.46198871 | EM10: =CM10 -> 10.417919 | EN10: =CO10 -> 11.989456 | EO10: =CN10 -> 8.0199833
A11: 2024 | B11: =SUM(datos!JF106:JF113) -> 132.25708 | C11: =SUM(datos!JG106:JG113) -> 204.61331 | D11: =SUM(datos!JH106:JH113) -> 1148.7857 | E11: =SUM(datos!JI106:JI113) -> 1530.8477 | F11: =SUM(datos!JJ106:JJ113) -> 5862.4109 | G11: =SUM(datos!JK106:JK113) -> 782.83545 | H11: =SUM(datos!JL106:JL113) -> 20031.984 | I11: =SUM(datos!JM106:JM113) -> 198.3859 | ... BK11: =SUM(datos!LO106:LO113) -> 26.138777 | BM11: 2024 | BN11: =B11 -> 132.25708 | BO11: =C11 -> 204.61331 | BP11: =SUM(D11:F11,H11:J11) -> 31324.669 | BQ11: =G11 -> 782.83545 | BR11: =K11 -> 245.60389 | BS11: =L11 -> 0 | BT11: =SUM(M11:P11) -> 59.575991 | BU11: =Q11 -> 626.51545 | BV11: =SUM(R11:S11) -> 313.84715 | BW11: =SUM(T11:W11) -> 239.31977 | BX11: =X11 -> 173.77075 | BY11: =Y11 -> 316.79907 | BZ11: =Z11 -> 75.501361 | CA11: =AA11 -> 139.5084 | CB11: =AB11 -> 233.39715 | CC11: =AC11 -> 2633.1533 | CD11: =AD11 -> 986.76099 | CE11: =AE11 -> 142.75738 | CF11: =AF11 -> 17.962228 | CG11: =SUM(BN11:CF11) -> 38648.848 | CH11: =CG11-BP11 -> 7324.1787 | CI11: =AG11 -> 37.5473 | CJ11: =AH11 -> 2.78077 | CK11: =SUM(AI11:AK11,AM11:AO11) -> 2270.3485 | CL11: =AL11 -> 2.0315312 | CM11: =AP11 -> 11.457533 | CN11: =AQ11 -> 0.92337464 | CO11: =SUM(AR11:AU11) -> 18.734589 | CP11: =AV11 -> 9.0850365 | CQ11: =SUM(AW11:AX11) -> 2.3328176 | CR11: =SUM(AY11:BB11) -> 4.0257754 | CS11: =BC11 -> 110.27094 | CT11: =BD11 -> 33.9591 | CU11: =BE11 -> 14.890542 | CV11: =BF11 -> 0.0525393 | CW11: =BG11 -> 22.650185 | CX11: =BH11 -> 21.836344 | CY11: =BI11 -> 12.885164 | CZ11: =BJ11 -> 2.2231297 | DA11: =BK11 -> 26.138777 | DB11: =SUM(CI11:DA11) -> 2604.174 | DC11: =DB11-CK11 -> 333.82545 | DD11: 2024 | DE11: =CC11 -> 2633.1533 | DF11: =CD11 -> 986.76099 | DG11: =CB11 -> 233.39715 | DH11: =CE11 -> 142.75738 | DI11: =CF11 -> 17.962228 | DJ11: =BU11 -> 626.51545 | DK11: =BZ11 -> 75.501361 | DL11: =BN11 -> 132.25708 | DM11: =BV11 -> 313.84715 | DN11: =BW11 -> 239.31977 | DO11: =BX11 -> 173.77075 | DP11: =BY11 -> 316.79907 | DQ11: =CA11 -> 139.5084 | DR11: =BO11 -> 204.61331 | DS11: =BQ11 -> 782.83545 | DT11: =BR11 -> 245.60389 | DU11: =BT11 -> 59.575991 | DV11: =BS11 -> 0 | DX11: =CX11 -> 21.836344 | DY11: =CY11 -> 12.885164 | DZ11: =CW11 -> 22.650185 | EA11: =CZ11 -> 2.2231297 | EB11: =DA11 -> 26.138777 | EC11: =CP11 -> 9.0850365 | ED11: =CU11 -> 14.890542 | EE11: =CI11 -> 37.5473 | EF11: =CQ11 -> 2.3328176 | EG11: =CR11 -> 4.0257754 | EH11: =CS11 -> 110.27094 | EI11: =CT11 -> 33.9591 | EJ11: =CV11 -> 0.0525393 | EK11: =CJ11 -> 2.78077 | EL11: =CL11 -> 2.0315312 | EM11: =CM11 -> 11.457533 | EN11: =CO11 -> 18.734589 | EO11: =CN11 -> 0.92337464
A12: 2025 | B12: =SUM(datos!JF118:JF125) -> 67.837281 | C12: =SUM(datos!JG118:JG125) -> 325.49616 | D12: =SUM(datos!JH118:JH125) -> 1051.9228 | E12: =SUM(datos!JI118:JI125) -> 1942.0605 | F12: =SUM(datos!JJ118:JJ125) -> 6019.2394 | G12: =SUM(datos!JK118:JK125) -> 864.23814 | H12: =SUM(datos!JL118:JL125) -> 17524.546 | I12: =SUM(datos!JM118:JM125) -> 305.37149 | ... BK12: =SUM(datos!LO118:LO125) -> 117.52479 | BM12: 2025 | BN12: =B12 -> 67.837281 | BO12: =C12 -> 325.49616 | BP12: =SUM(D12:F12,H12:J12) -> 29720.179 | BQ12: =G12 -> 864.23814 | BR12: =K12 -> 249.51668 | BS12: =L12 -> 0 | BT12: =SUM(M12:P12) -> 37.565798 | BU12: =Q12 -> 610.25239 | BV12: =SUM(R12:S12) -> 337.41537 | BW12: =SUM(T12:W12) -> 334.4399 | BX12: =X12 -> 104.92459 | BY12: =Y12 -> 364.61011 | BZ12: =Z12 -> 74.724022 | CA12: =AA12 -> 160.61636 | CB12: =AB12 -> 57.796366 | CC12: =AC12 -> 3062.1674 | CD12: =AD12 -> 1111.746 | CE12: =AE12 -> 166.30928 | CF12: =AF12 -> 17.024898 | CG12: =SUM(BN12:CF12) -> 37666.86 | CH12: =CG12-BP12 -> 7946.6808 | CI12: =AG12 -> 76.923617 | CJ12: =AH12 -> 2.8490507 | CK12: =SUM(AI12:AK12,AM12:AO12) -> 1892.5688 | CL12: =AL12 -> 1.5462054 | CM12: =AP12 -> 7.0975334 | CN12: =AQ12 -> 2.1868104 | CO12: =SUM(AR12:AU12) -> 9.5226502 | CP12: =AV12 -> 24.642074 | CQ12: =SUM(AW12:AX12) -> 4.4398865 | CR12: =SUM(AY12:BB12) -> 17.550539 | CS12: =BC12 -> 120.56186 | CT12: =BD12 -> 34.164904 | CU12: =BE12 -> 17.123049 | CV12: =BF12 -> 0.04522687 | CW12: =BG12 -> 26.151564 | CX12: =BH12 -> 67.500707 | CY12: =BI12 -> 20.243999 | CZ12: =BJ12 -> 1.2200566 | DA12: =BK12 -> 117.52479 | DB12: =SUM(CI12:DA12) -> 2443.8633 | DC12: =DB12-CK12 -> 551.29452 | DD12: 2025 | DE12: =CC12 -> 3062.1674 | DF12: =CD12 -> 1111.746 | DG12: =CB12 -> 57.796366 | DH12: =CE12 -> 166.30928 | DI12: =CF12 -> 17.024898 | DJ12: =BU12 -> 610.25239 | DK12: =BZ12 -> 74.724022 | DL12: =BN12 -> 67.837281 | DM12: =BV12 -> 337.41537 | DN12: =BW12 -> 334.4399 | DO12: =BX12 -> 104.92459 | DP12: =BY12 -> 364.61011 | DQ12: =CA12 -> 160.61636 | DR12: =BO12 -> 325.49616 | DS12: =BQ12 -> 864.23814 | DT12: =BR12 -> 249.51668 | DU12: =BT12 -> 37.565798 | DV12: =BS12 -> 0 | DX12: =CX12 -> 67.500707 | DY12: =CY12 -> 20.243999 | DZ12: =CW12 -> 26.151564 | EA12: =CZ12 -> 1.2200566 | EB12: =DA12 -> 117.52479 | EC12: =CP12 -> 24.642074 | ED12: =CU12 -> 17.123049 | EE12: =CI12 -> 76.923617 | EF12: =CQ12 -> 4.4398865 | EG12: =CR12 -> 17.550539 | EH12: =CS12 -> 120.56186 | EI12: =CT12 -> 34.164904 | EJ12: =CV12 -> 0.04522687 | EK12: =CJ12 -> 2.8490507 | EL12: =CL12 -> 1.5462054 | EM12: =CM12 -> 7.0975334 | EN12: =CO12 -> 9.5226502 | EO12: =CN12 -> 2.1868104
A13: 2026 | B13: =SUM(datos!JF130:JF137) -> 120.8521 | C13: =SUM(datos!JG130:JG137) -> 293.9775 | D13: =SUM(datos!JH130:JH137) -> 1506.6423 | E13: =SUM(datos!JI130:JI137) -> 3878.3831 | F13: =SUM(datos!JJ130:JJ137) -> 6943.3568 | G13: =SUM(datos!JK130:JK137) -> 867.33654 | H13: =SUM(datos!JL130:JL137) -> 17983.647 | I13: =SUM(datos!JM130:JM137) -> 251.89073 | ... BK13: =SUM(datos!LO130:LO137) -> 126.8555 | BM13: 2026 | BN13: =B13 -> 120.8521 | BO13: =C13 -> 293.9775 | BP13: =SUM(D13:F13,H13:J13) -> 34060.531 | BQ13: =G13 -> 867.33654 | BR13: =K13 -> 259.05938 | BS13: =L13 -> 0 | BT13: =SUM(M13:P13) -> 48.080469 | BU13: =Q13 -> 546.33289 | BV13: =SUM(R13:S13) -> 327.94638 | BW13: =SUM(T13:W13) -> 434.84178 | BX13: =X13 -> 134.14277 | BY13: =Y13 -> 402.16041 | BZ13: =Z13 -> 78.965883 | CA13: =AA13 -> 244.39321 | CB13: =AB13 -> 67.080908 | CC13: =AC13 -> 4123.6159 | CD13: =AD13 -> 1202.1987 | CE13: =AE13 -> 271.1013 | CF13: =AF13 -> 26.464585 | CG13: =SUM(BN13:CF13) -> 43509.082 | CH13: =CG13-BP13 -> 9448.5507 | CI13: =AG13 -> 46.811962 | CJ13: =AH13 -> 1.2966958 | CK13: =SUM(AI13:AK13,AM13:AO13) -> 2779.0437 | CL13: =AL13 -> 0.5665194 | CM13: =AP13 -> 17.760967 | CN13: =AQ13 -> 7.1763511 | CO13: =SUM(AR13:AU13) -> 14.367727 | CP13: =AV13 -> 25.265352 | CQ13: =SUM(AW13:AX13) -> 6.1102159 | CR13: =SUM(AY13:BB13) -> 6.7373456 | CS13: =BC13 -> 128.3066 | CT13: =BD13 -> 35.879582 | CU13: =BE13 -> 15.53136 | CV13: =BF13 -> 0.0062559 | CW13: =BG13 -> 29.704679 | CX13: =BH13 -> 123.26888 | CY13: =BI13 -> 21.562201 | CZ13: =BJ13 -> 1.5229212 | DA13: =BK13 -> 126.8555 | DB13: =SUM(CI13:DA13) -> 3387.7748 | DC13: =DB13-CK13 -> 608.73112 | DD13: 2026 | DE13: =CC13 -> 4123.6159 | DF13: =CD13 -> 1202.1987 | DG13: =CB13 -> 67.080908 | DH13: =CE13 -> 271.1013 | DI13: =CF13 -> 26.464585 | DJ13: =BU13 -> 546.33289 | DK13: =BZ13 -> 78.965883 | DL13: =BN13 -> 120.8521 | DM13: =BV13 -> 327.94638 | DN13: =BW13 -> 434.84178 | DO13: =BX13 -> 134.14277 | DP13: =BY13 -> 402.16041 | DQ13: =CA13 -> 244.39321 | DR13: =BO13 -> 293.9775 | DS13: =BQ13 -> 867.33654 | DT13: =BR13 -> 259.05938 | DU13: =BT13 -> 48.080469 | DV13: =BS13 -> 0 | DX13: =CX13 -> 123.26888 | DY13: =CY13 -> 21.562201 | DZ13: =CW13 -> 29.704679 | EA13: =CZ13 -> 1.5229212 | EB13: =DA13 -> 126.8555 | EC13: =CP13 -> 25.265352 | ED13: =CU13 -> 15.53136 | EE13: =CI13 -> 46.811962 | EF13: =CQ13 -> 6.1102159 | EG13: =CR13 -> 6.7373456 | EH13: =CS13 -> 128.3066 | EI13: =CT13 -> 35.879582 | EJ13: =CV13 -> 0.0062559 | EK13: =CJ13 -> 1.2966958 | EL13: =CL13 -> 0.5665194 | EM13: =CM13 -> 17.760967 | EN13: =CO13 -> 14.367727 | EO13: =CN13 -> 7.1763511
CG14: =CG13/CG12-1 -> 0.15510244 | DA14: =DA13/DA12-1 -> 0.079393579
BN15: =BN13/$CH13 -> 0.012790543 | BO15: =BO13/$CH13 -> 0.031113502 | BQ15: =BQ13/$CH13 -> 0.091795723 | BR15: =BR13/$CH13 -> 0.027417896 | BS15: =BS13/$CH13 -> 0 | BT15: =BT13/$CH13 -> 0.0050886607 | BU15: =BU13/$CH13 -> 0.057821872 | BV15: =BV13/$CH13 -> 0.034708644 | BW15: =BW13/$CH13 -> 0.046022061 | BX15: =BX13/$CH13 -> 0.01419718 | ... CF15: =CF13/$CH13 -> 0.0028009147 | CI15: =CI13/$DC13 -> 0.076900886 | CJ15: =CJ13/$DC13 -> 0.0021301618 | CL15: =CL13/$DC13 -> 0.00093065622 | CM15: =CM13/$DC13 -> 0.029177031 | CN15: =CN13/$DC13 -> 0.011789033 | CO15: =CO13/$DC13 -> 0.023602747 | CP15: =CP13/$DC13 -> 0.041504946 | CQ15: =CQ13/$DC13 -> 0.010037627 | CR15: =CR13/$DC13 -> 0.011067852 | CS15: =CS13/$DC13 -> 0.21077714 | ... DA15: =DA13/$DC13 -> 0.20839332
A16: Promedio ultimos 5 años | B16: =AVERAGE(B7:B12) -> 98.274356 | C16: =AVERAGE(C7:C12) -> 201.96433 | D16: =AVERAGE(D7:D12) -> 1117.695 | E16: =AVERAGE(E7:E12) -> 1766.9207 | F16: =AVERAGE(F7:F12) -> 6241.5652 | G16: =AVERAGE(G7:G12) -> 813.57122 | H16: =AVERAGE(H7:H12) -> 18970.821 | I16: =AVERAGE(I7:I12) -> 290.08197 | ... BK16: =AVERAGE(BK7:BK12) -> 62.724135 | BM16: Prom | BN16: =AVERAGE(BN3:BN12) -> 83.708364 | BO16: =AVERAGE(BO3:BO12) -> 172.09293 | BP16: =AVERAGE(BP3:BP12) -> 25608.545 | BQ16: =AVERAGE(BQ3:BQ12) -> 699.88979 | BR16: =AVERAGE(BR3:BR12) -> 176.26866 | BS16: =AVERAGE(BS3:BS12) -> 0.0004164 | BT16: =AVERAGE(BT3:BT12) -> 38.341733 | BU16: =AVERAGE(BU3:BU12) -> 631.86878 | ... CF16: =AVERAGE(CF3:CF12) -> 21.565829 | CG16: =AVERAGE(CG7:CG12) -> 38839.662 | CI16: =AVERAGE(CI3:CI12) -> 61.711235 | CJ16: =AVERAGE(CJ3:CJ12) -> 2.4500982 | CK16: =AVERAGE(CK3:CK12) -> 1797.2403 | CL16: =AVERAGE(CL3:CL12) -> 0.64866151 | CM16: =AVERAGE(CM3:CM12) -> 14.536617 | CN16: =AVERAGE(CN3:CN12) -> 3.2481471 | CO16: =AVERAGE(CO3:CO12) -> 20.219173 | CP16: =AVERAGE(CP3:CP12) -> 13.687346 | ... DA16: =AVERAGE(DA3:DA12) -> 64.584732 | DB16: =AVERAGE(DB7:DB12) -> 2803.3564 | DC16: =AVERAGE(DC7:DC12) -> 472.77014
B17: =B13/B16-1 -> 0.22974194 | C17: =C13/C16-1 -> 0.4555912 | D17: =D13/D16-1 -> 0.34799051 | E17: =E13/E16-1 -> 1.1949955 | F17: =F13/F16-1 -> 0.1124384 | G17: =G13/G16-1 -> 0.066085568 | H17: =H13/H16-1 -> -0.052036428 | I17: =I13/I16-1 -> -0.13165674 | ... BK17: =BK13/BK16-1 -> 1.0224352 | BN17: =BN13/BN16-1 -> 0.44372785 | BO17: =BO13/BO16-1 -> 0.70824858 | BP17: =BP13/BP16-1 -> 0.33004555 | BQ17: =BQ13/BQ16-1 -> 0.2392473 | BR17: =BR13/BR16-1 -> 0.46968488 | BS17: 0 | BT17: =BT13/BT16-1 -> 0.2539983 | BU17: =BU13/BU16-1 -> -0.13536971 | BV17: =BV13/BV16-1 -> 0.041445109 | BW17: =BW13/BW16-1 -> 0.26561029 | BX17: =BX13/BX16-1 -> -0.097284543 | BY17: =BY13/BY16-1 -> 0.63663292 | BZ17: =BZ13/BZ16-1 -> 0.1925065 | CA17: =CA13/CA16-1 -> 0.65422111 | ... CG17: =CG13/CG16-1 -> 0.12022299 | CH17: =CG13/CG12-1 -> 0.15510244 | CI17: =CI13/CI16-1 -> -0.24143534 | CJ17: =CJ13/CJ16-1 -> -0.47075763 | CK17: =CK13/CK16-1 -> 0.54628389 | CL17: =CL13/CL16-1 -> -0.12663325 | CM17: =CM13/CM16-1 -> 0.2218088 | CN17: =CN13/CN16-1 -> 1.2093677 | CO17: =CO13/CO16-1 -> -0.28940085 | CP17: =CP13/CP16-1 -> 0.8458912 | ... DC17: =DC13/DC16-1 -> 0.28758369
A19: 2016 | F19: =D13+E13+F13+H13+I13+J13 -> 34060.531 | BM19: 2016 | BN19: =BN3/$CG3 -> 0.0023411959 | BO19: =BO3/$CG3 -> 0.0064314434 | BP19: =BP3/$CG3 -> 0.78352373 | BQ19: =BQ3/$CG3 -> 0.025992501 | BR19: =BR3/$CG3 -> 0.0062686993 | BS19: =BS3/$CG3 -> 0 | BT19: =BT3/$CG3 -> 0.0012258662 | BU19: =BU3/$CG3 -> 0.027903825 | ... CF19: =CF3/$CG3 -> 0.00030258904 | CI19: =CI3/$DB3 -> 0.12213449 | CJ19: =CJ3/$DB3 -> 0.0056763937 | CK19: =CK3/$DB3 -> 0.34755386 | CL19: =CL3/$DB3 -> 0.0001730974 | CM19: =CM3/$DB3 -> 0.025345975 | CN19: =CN3/$DB3 -> 0.0011787051 | CO19: =CO3/$DB3 -> 0.039471439 | CP19: =CP3/$DB3 -> 0.0038472473 | ... DA19: =DA3/$DB3 -> 0.063013429 | DC19: =CG13/DB13 -> 12.842968
A20: 2017 | D20: =D13/$F19 -> 0.044234257 | E20: =E13/$F19 -> 0.11386737 | F20: =F13/$F19 -> 0.20385345 | H20: =H13/$F19 -> 0.5279908 | I20: =I13/$F19 -> 0.0073953845 | J20: =J13/$F19 -> 0.10265874 | BM20: 2017 | BN20: =BN4/$CG4 -> 0.0022604194 | BO20: =BO4/$CG4 -> 0.0057861147 | BP20: =BP4/$CG4 -> 0.77187891 | BQ20: =BQ4/$CG4 -> 0.025547084 | BR20: =BR4/$CG4 -> 0.0057013473 | BS20: =BS4/$CG4 -> 7.5886385e-08 | BT20: =BT4/$CG4 -> 0.00075697538 | BU20: =BU4/$CG4 -> 0.028026056 | ... CF20: =CF4/$CG4 -> 0.00057182909 | CI20: =CI4/$DB4 -> 0.059271304 | CJ20: =CJ4/$DB4 -> 0.0033089794 | CK20: =CK4/$DB4 -> 0.51269676 | CL20: =CL4/$DB4 -> 0.00059880301 | CM20: =CM4/$DB4 -> 0.021039928 | CN20: =CN4/$DB4 -> 0.0039957321 | CO20: =CO4/$DB4 -> 0.028575948 | CP20: =CP4/$DB4 -> 0.045444786 | ... DA20: =DA4/$DB4 -> 0.071799491 | DC20: =CH13/DC13 -> 15.521715
A21: 2018 | BM21: 2018 | BN21: =BN5/$CG5 -> 0.0032132163 | BO21: =BO5/$CG5 -> 0.005957427 | BP21: =BP5/$CG5 -> 0.73417258 | BQ21: =BQ5/$CG5 -> 0.022452058 | BR21: =BR5/$CG5 -> 0.0054615355 | BS21: =BS5/$CG5 -> 0 | BT21: =BT5/$CG5 -> 0.0015012066 | BU21: =BU5/$CG5 -> 0.030886973 | ... CF21: =CF5/$CG5 -> 0.00069813272 | CI21: =CI5/$DB5 -> 0.032294509 | CJ21: =CJ5/$DB5 -> 0.0015281927 | CK21: =CK5/$DB5 -> 0.77355356 | CL21: =CL5/$DB5 -> 9.6366095e-05 | CM21: =CM5/$DB5 -> 0.016137717 | CN21: =CN5/$DB5 -> 0.0019390407 | CO21: =CO5/$DB5 -> 0.01198667 | CP21: =CP5/$DB5 -> 0.003312709 | ... DA21: =DA5/$DB5 -> 0.036158778
A22: 2019 | BM22: 2019 | BN22: =BN6/$CG6 -> 0.0032798124 | BO22: =BO6/$CG6 -> 0.0046686957 | BP22: =BP6/$CG6 -> 0.7595458 | BQ22: =BQ6/$CG6 -> 0.020823035 | BR22: =BR6/$CG6 -> 0.0062732631 | BS22: =BS6/$CG6 -> 0 | BT22: =BT6/$CG6 -> 0.001674092 | BU22: =BU6/$CG6 -> 0.026862972 | ... CF22: =CF6/$CG6 -> 0.00055987543 | CI22: =CI6/$DB6 -> 0.02618127 | CJ22: =CJ6/$DB6 -> 0.001294072 | CK22: =CK6/$DB6 -> 0.77549749 | CL22: =CL6/$DB6 -> 9.4010274e-05 | CM22: =CM6/$DB6 -> 0.0073570011 | CN22: =CN6/$DB6 -> 0.0008399645 | CO22: =CO6/$DB6 -> 0.0073279611 | CP22: =CP6/$DB6 -> 0.0028699059 | ... DA22: =DA6/$DB6 -> 0.034399972
A23: 2020 | BM23: 2020 | BN23: =BN7/$CG7 -> 0.0026305014 | BO23: =BO7/$CG7 -> 0.0044256429 | BP23: =BP7/$CG7 -> 0.77559317 | BQ23: =BQ7/$CG7 -> 0.026029185 | BR23: =BR7/$CG7 -> 0.004325946 | BS23: =BS7/$CG7 -> 8.3789649e-08 | BT23: =BT7/$CG7 -> 0.0014921909 | BU23: =BU7/$CG7 -> 0.021127628 | ... CF23: =CF7/$CG7 -> 0.0017649559 | CI23: =CI7/$DB7 -> 0.017645018 | CJ23: =CJ7/$DB7 -> 0.0017868425 | CK23: =CK7/$DB7 -> 0.79148048 | CL23: =CL7/$DB7 -> 0.00015237975 | CM23: =CM7/$DB7 -> 0.0074301772 | CN23: =CN7/$DB7 -> 0.00087124685 | CO23: =CO7/$DB7 -> 0.015393771 | CP23: =CP7/$DB7 -> 0.0028079583 | ... DA23: =DA7/$DB7 -> 0.021577192
A24: 2021 | BM24: 2021 | BN24: =BN8/$CG8 -> 0.0025201905 | BO24: =BO8/$CG8 -> 0.0042167906 | BP24: =BP8/$CG8 -> 0.83606339 | BQ24: =BQ8/$CG8 -> 0.017691847 | BR24: =BR8/$CG8 -> 0.004165964 | BS24: =BS8/$CG8 -> 0 | BT24: =BT8/$CG8 -> 0.00084739728 | BU24: =BU8/$CG8 -> 0.014801287 | ... CF24: =CF8/$CG8 -> 0.0012920845 | CI24: =CI8/$DB8 -> 0.021111724 | CJ24: =CJ8/$DB8 -> 0.00046868925 | CK24: =CK8/$DB8 -> 0.81296079 | CL24: =CL8/$DB8 -> 0.00014133167 | CM24: =CM8/$DB8 -> 0.0027799915 | CN24: =CN8/$DB8 -> 0.00087962135 | CO24: =CO8/$DB8 -> 0.006112237 | CP24: =CP8/$DB8 -> 0.0038706766 | ... DA24: =DA8/$DB8 -> 0.02627891
A25: 2022 | BM25: 2022 | BN25: =BN9/$CG9 -> 0.0033875981 | BO25: =BO9/$CG9 -> 0.0034514824 | BP25: =BP9/$CG9 -> 0.82857379 | BQ25: =BQ9/$CG9 -> 0.01604501 | BR25: =BR9/$CG9 -> 0.0040976217 | BS25: =BS9/$CG9 -> 0 | BT25: =BT9/$CG9 -> 0.00084087617 | BU25: =BU9/$CG9 -> 0.014119632 | ... CF25: =CF9/$CG9 -> 0.00020538308 | CI25: =CI9/$DB9 -> 0.02989455 | CJ25: =CJ9/$DB9 -> 0.00020074077 | CK25: =CK9/$DB9 -> 0.77317762 | CL25: =CL9/$DB9 -> 0.00024205321 | CM25: =CM9/$DB9 -> 0.002045795 | CN25: =CN9/$DB9 -> 0.0025039816 | CO25: =CO9/$DB9 -> 0.0070344364 | CP25: =CP9/$DB9 -> 0.0043628764 | ... DA25: =DA9/$DB9 -> 0.032287198
A26: 2023 | BM26: 2023 | BN26: =BN10/$CG10 -> 0.0009333275 | BO26: =BO10/$CG10 -> 0.0058274828 | BP26: =BP10/$CG10 -> 0.77608346 | BQ26: =BQ10/$CG10 -> 0.026701746 | BR26: =BR10/$CG10 -> 0.0066808254 | BS26: =BS10/$CG10 -> 0 | BT26: =BT10/$CG10 -> 0.0014311121 | BU26: =BU10/$CG10 -> 0.017091885 | ... CF26: =CF10/$CG10 -> 0.00040915478 | CI26: =CI10/$DB10 -> 0.013877292 | CJ26: =CJ10/$DB10 -> 7.080545e-05 | CK26: =CK10/$DB10 -> 0.89459729 | CL26: =CL10/$DB10 -> 9.6382327e-05 | CM26: =CM10/$DB10 -> 0.0021734369 | CN26: =CN10/$DB10 -> 0.0016731678 | CO26: =CO10/$DB10 -> 0.0025012986 | CP26: =CP10/$DB10 -> 0.0021805974 | ... DA26: =DA10/$DB10 -> 0.0088995948
A27: 2024 | BM27: 2024 | BN27: =BN11/$CG11 -> 0.0034220186 | BO27: =BO11/$CG11 -> 0.0052941633 | BP27: =BP11/$CG11 -> 0.81049426 | BQ27: =BQ11/$CG11 -> 0.020255078 | BR27: =BR11/$CG11 -> 0.0063547532 | BS27: =BS11/$CG11 -> 0 | BT27: =BT11/$CG11 -> 0.0015414687 | BU27: =BU11/$CG11 -> 0.016210456 | ... CF27: =CF11/$CG11 -> 0.00046475455 | CI27: =CI11/$DB11 -> 0.014418123 | CJ27: =CJ11/$DB11 -> 0.0010678127 | CK27: =CK11/$DB11 -> 0.87181139 | CL27: =CL11/$DB11 -> 0.00078010578 | CM27: =CM11/$DB11 -> 0.0043996804 | CN27: =CN11/$DB11 -> 0.00035457487 | CO27: =CO11/$DB11 -> 0.0071940622 | CP27: =CP11/$DB11 -> 0.0034886442 | ... DA27: =DA11/$DB11 -> 0.010037262
A28: 2025 | BM28: 2025 | BN28: =BN12/$CG12 -> 0.0018009805 | BO28: =BO12/$CG12 -> 0.0086414465 | BP28: =BP12/$CG12 -> 0.78902726 | BQ28: =BQ12/$CG12 -> 0.022944258 | BR28: =BR12/$CG12 -> 0.0066243027 | BS28: =BS12/$CG12 -> 0 | BT28: =BT12/$CG12 -> 0.00099731695 | BU28: =BU12/$CG12 -> 0.016201308 | ... CF28: =CF12/$CG12 -> 0.00045198613 | CI28: =CI12/$DB12 -> 0.031476235 | CJ28: =CJ12/$DB12 -> 0.0011657979 | CK28: =CK12/$DB12 -> 0.77441679 | CL28: =CL12/$DB12 -> 0.00063268897 | CM28: =CM12/$DB12 -> 0.0029042268 | CN28: =CN12/$DB12 -> 0.000894817 | CO28: =CO12/$DB12 -> 0.003896556 | CP28: =CP12/$DB12 -> 0.010083246 | ... DA28: =DA12/$DB12 -> 0.048089755
A29: 2026 | BM29: 2026 | BN29: =BN13/$CG13 -> 0.0027776292 | BO29: =BO13/$CG13 -> 0.0067566927 | BP29: =BP13/$CG13 -> 0.78283728 | BQ29: =BQ13/$CG13 -> 0.019934609 | BR29: =BR13/$CG13 -> 0.0059541449 | BS29: =BS13/$CG13 -> 0 | BT29: =BT13/$CG13 -> 0.0011050674 | BU29: =BU13/$CG13 -> 0.012556755 | ... CF29: =CF13/$CG13 -> 0.00060825426 | CI29: =CI13/$DB13 -> 0.013817909 | CJ29: =CJ13/$DB13 -> 0.00038275736 | CK29: =CK13/$DB13 -> 0.82031535 | CL29: =CL13/$DB13 -> 0.00016722463 | CM29: =CM13/$DB13 -> 0.0052426646 | CN29: =CN13/$DB13 -> 0.0021183082 | CO29: =CO13/$DB13 -> 0.0042410514 | CP29: =CP13/$DB13 -> 0.0074578016 | ... DA29: =DA13/$DB13 -> 0.037445081
BM31: Prom | BN31: =AVERAGE(BN23:BN28) -> 0.0024491028 | BO31: =AVERAGE(BO23:BO28) -> 0.0053095014 | BP31: =AVERAGE(BP23:BP28) -> 0.80263922 | BQ31: =AVERAGE(BQ23:BQ28) -> 0.021611187 | BR31: =AVERAGE(BR23:BR28) -> 0.0053749022 | BS31: =AVERAGE(BS23:BS28) -> 1.3964941e-08 | BT31: =AVERAGE(BT23:BT28) -> 0.001191727 | BU31: =AVERAGE(BU23:BU28) -> 0.016592033 | ... CF31: =AVERAGE(CF23:CF28) -> 0.00076471983 | CI31: =AVERAGE(CI24:CI29) -> 0.020765972 | CJ31: =AVERAGE(CJ24:CJ29) -> 0.0005594339 | CK31: =AVERAGE(CK24:CK29) -> 0.82454654 | CL31: =AVERAGE(CL24:CL29) -> 0.00034329776 | CM31: =AVERAGE(CM24:CM29) -> 0.0032576325 | CN31: =AVERAGE(CN24:CN29) -> 0.0014040785 | CO31: =AVERAGE(CO24:CO29) -> 0.0051632736 | CP31: =AVERAGE(CP24:CP29) -> 0.0052406403 | ... DA31: =AVERAGE(DA24:DA29) -> 0.027172967
BP32: 1 | BQ32: 4 | BU32: 5 | CC32: 2 | CD32: 3
CV33: =CV13*1000000 -> 6255.9 | CX33: =CX13/CX12-1 -> 0.82618652
CE34: =80%+9% -> 0.89
CE35: 1 | CF35: =CE35-CE34 -> 0.11
CE36: =BP13+CC13 -> 38184.147
CE37: =CG13-CE36 -> 5324.9348

Sheet PP
B1: Arroz | D1: Vino | F1: Trigo | H1: Bovino | J1: Porcino | L1: Aviar | N1: Ovino | P1: Yerba | R1: Leche | W1: Papa | AD1: Hortalizas | AK1: Participacion del Productor | AX1: https://fetra.org.ar/tarifas.php?anio=2026
F2: =0.75*1.09 -> 0.8175 | H2: =0.58*0.76 -> 0.4408 | J2: =0.8*0.75 -> 0.6 | L2: 0.7 | N2: =0.54*0.7 -> 0.378 | P2: 0.34 | Q2: 2 | AX2: Actualizaciones
B3: $/kg | D3: $/lt | F3: $/kg | H3: $/kg | J3: $/kg | L3: $/kg | N3: $/kg | P3: $/kg | R3: $/lt | W3: $ Mayorista | X3: Comision | Y3: Gastos | Z3: Flete | AB3: 20 | AD3: $ Mayorista | AE3: Comision | AF3: Gastos | AG3: Flete | AH3: 18 | AX3: FETRA
B4: P.P | C4: P.C | D4: P.P | E4: P.C | F4: P.P | G4: P.C | H4: P.P | I4: P.C | J4: P.P | K4: P.C | L4: P.P | M4: P.C | N4: P.P | O4: P.C | P4: P.P | Q4: P.C | R4: P.P | S4: % GB | T4: precio sol.utiles | V4: P.C | W4: 1 | X4: 0.08 | Z4: % | AB4: P.P | AC4: P.C | AD4: 1 | AE4: 0.08 | AH4: P.P | AI4: P.C | AL4: Arroz | AM4: Vino | AN4: Trigo | AO4: Bovino | AP4: Porcino | AQ4: Aviar | AR4: Ovino | AS4: Yerba | AT4: Leche | AU4: Papa | AV4: Hortalizas | AY4: $/tn/kg | AZ4: %
A5: 42370 | B5: =datos!R10/1000 -> 2.1 | D5: =datos!AI10 -> 3.4258 | F5: =(datos!AD10/1000)/PP!$F$2 -> 2.3743329 | H5: =datos!BK10/$H$2 -> 57.899274 | I5: =datos!NB10 -> 109.1 | J5: =datos!BR10/$J$2 -> 24.45 | K5: =datos!NE10 -> 84.93 | L5: =datos!BO10*$L$2 -> 12.41065 | M5: =datos!NA10 -> 32.66 | N5: =datos!BS10*$N$2 -> 21.924 | P5: =(datos!AG10/1000)/$P$2 -> 12.564706 | R5: =datos!BN10 -> 2.75 | W5: =datos!AV10*W$4 -> 63.8 | X5: =W5*X$4 -> 5.104 | Y5: =Y6/(1+(datos!G11/datos!G10-1)) -> 3.2881411 | AD5: =datos!BB10*AD$4 -> 97.835 | AE5: =AD5*AE$4 -> 7.8268 | AF5: =Y5 -> 3.2881411 | AK5: =A5 -> 42370 | AO5: =H5/I5 -> 0.53069912 | AP5: =J5/K5 -> 0.28788414 | AQ5: =L5/M5 -> 0.37999541 | AX5: Feb-22 - Mar-22 | AY5: 578.25
A6: 42401 | B6: =datos!R11/1000 -> 2.05 | D6: =datos!AI11 -> 3.67 | F6: =(datos!AD11/1000)/PP!$F$2 -> 2.4720931 | H6: =datos!BK11/$H$2 -> 59.947822 | I6: =datos!NB11 -> 104.08 | J6: =datos!BR11/$J$2 -> 24.8 | K6: =datos!NE11 -> 84.97 | L6: =datos!BO11*$L$2 -> 14.372474 | M6: =datos!NA11 -> 33.23 | N6: =datos!BS11*$N$2 -> 21.546 | P6: =(datos!AG11/1000)/$P$2 -> 12.564706 | R6: =datos!BN11 -> 2.806 | W6: =datos!AV11*W$4 -> 60.6 | X6: =W6*X$4 -> 4.848 | Y6: =Y7/(1+(datos!G12/datos!G11-1)) -> 3.4415758 | AD6: =datos!BB11*AD$4 -> 275.947 | AE6: =AD6*AE$4 -> 22.07576 | AF6: =Y6 -> 3.4415758 | AK6: =A6 -> 42401 | AO6: =H6/I6 -> 0.57597831 | AP6: =J6/K6 -> 0.29186772 | AQ6: =L6/M6 -> 0.43251501 | AX6: Abr-22 - May-22 | AY6: 693.9 | AZ6: =AY6/AY5-1 -> 0.2
A7: 42430 | B7: =datos!R12/1000 -> 2.05 | D7: =datos!AI12 -> 4.63 | F7: =(datos!AD12/1000)/PP!$F$2 -> 2.644278 | H7: =datos!BK12/$H$2 -> 61.876134 | I7: =datos!NB12 -> 104.06 | J7: =datos!BR12/$J$2 -> 24.566667 | K7: =datos!NE12 -> 85.26 | L7: =datos!BO12*$L$2 -> 14.941333 | M7: =datos!NA12 -> 36.09 | N7: =datos!BS12*$N$2 -> 21.546 | P7: =(datos!AG12/1000)/$P$2 -> 12.564706 | R7: =datos!BN12 -> 2.89 | W7: =datos!AV12*W$4 -> 63.8 | X7: =W7*X$4 -> 5.104 | Y7: =Y8/(1+(datos!G13/datos!G12-1)) -> 3.5414867 | AD7: =datos!BB12*AD$4 -> 127.895 | AE7: =AD7*AE$4 -> 10.2316 | AF7: =Y7 -> 3.5414867 | AK7: =A7 -> 42430 | AO7: =H7/I7 -> 0.59461978 | AP7: =J7/K7 -> 0.28813824 | AQ7: =L7/M7 -> 0.41400203 | AX7: Jun-22 - Oct-22 | AY7: 802.92 | AZ7: =AY7/AY6-1 -> 0.15711198
A8: 42461 | B8: =datos!R13/1000 -> 2.15 | C8: =datos!MA13 -> 16.21 | D8: =datos!AI13 -> 5.31 | E8: =datos!MP13 -> 17.15 | F8: =(datos!AD13/1000)/PP!$F$2 -> 2.8187279 | G8: =datos!MH13 -> 29.85 | H8: =datos!BK13/$H$2 -> 65.830309 | I8: =datos!NB13 -> 104.5 | J8: =datos!BR13/$J$2 -> 24.35 | K8: =datos!NE13 -> 85.38 | L8: =datos!BO13*$L$2 -> 13.095 | M8: =datos!NA13 -> 34.25 | N8: =datos!BS13*$N$2 -> 22.302 | P8: =(datos!AG13/1000)/$P$2 -> 14.126471 | Q8: =datos!MY13*$Q$2 -> 52.58 | R8: =datos!BN13 -> 3.347 | U8: =T8*S8 -> 0 | V8: =datos!NC13+U8 -> 14.37 | W8: =datos!AV13*W$4 -> 71.2 | X8: =W8*X$4 -> 5.696 | Y8: =Y9/(1+(datos!G14/datos!G13-1)) -> 3.7537975 | AC8: =datos!MJ13 -> 9.26 | AD8: =datos!BB13*AD$4 -> 147.255 | AE8: =AD8*AE$4 -> 11.7804 | AF8: =Y8 -> 3.7537975 | AI8: =AVERAGE(datos!ML13,datos!MM13,datos!MN13,datos!MO13) -> 15.303333 | AK8: =A8 -> 42461 | AL8: =B8/C8 -> 0.13263418 | AM8: =D8/E8 -> 0.30962099 | AN8: =F8/G8 -> 0.094429747 | AO8: =H8/I8 -> 0.62995511 | AP8: =J8/K8 -> 0.2851956 | AQ8: =L8/M8 -> 0.38233577 | AS8: =P8/Q8 -> 0.26866623 | AX8: Nov-22 - Ene-23 | AY8: 1086.65 | AZ8: =AY8/AY7-1 -> 0.35337269
A9: 42491 | B9: =datos!R14/1000 -> 2.5 | C9: =datos!MA14 -> 16.32 | D9: =datos!AI14 -> 6.49 | E9: =datos!MP14 -> 20.61 | F9: =(datos!AD14/1000)/PP!$F$2 -> 3.177648 | G9: =datos!MH14 -> 30.85 | H9: =datos!BK14/$H$2 -> 68.464156 | I9: =datos!NB14 -> 106.67 | J9: =datos!BR14/$J$2 -> 23.616667 | K9: =datos!NE14 -> 84.98 | L9: =datos!BO14*$L$2 -> 13.0165 | M9: =datos!NA14 -> 33.04 | N9: =datos!BS14*$N$2 -> 22.302 | P9: =(datos!AG14/1000)/$P$2 -> 14.126471 | Q9: =datos!MY14*$Q$2 -> 53.2 | R9: =datos!BN14 -> 3.961 | U9: =T9*S9 -> 0 | V9: =datos!NC14+U9 -> 15.65 | W9: =datos!AV14*W$4 -> 79.8 | X9: =W9*X$4 -> 6.384 | Y9: =Y10/(1+(datos!G15/datos!G14-1)) -> 3.8965275 | AC9: =datos!MJ14 -> 9.44 | AD9: =datos!BB14*AD$4 -> 184.615 | AE9: =AD9*AE$4 -> 14.7692 | AF9: =Y9 -> 3.8965275 | AI9: =AVERAGE(datos!ML14,datos!MM14,datos!MN14,datos!MO14) -> 18.266667 | AK9: =A9 -> 42491 | AL9: =B9/C9 -> 0.15318627 | AM9: =D9/E9 -> 0.31489568 | AN9: =F9/G9 -> 0.10300318 | AO9: =H9/I9 -> 0.64183141 | AP9: =J9/K9 -> 0.27790853 | AQ9: =L9/M9 -> 0.39396186 | AS9: =P9/Q9 -> 0.26553516 | AX9: Feb-23 - May-23 | AY9: 1325.71 | AZ9: =AY9/AY8-1 -> 0.21999724
A10: 42522 | B10: =datos!R15/1000 -> 2.75 | C10: =datos!MA15 -> 16.6 | D10: =datos!AI15 -> 7.23 | E10: =datos!MP15 -> 23.2 | F10: =(datos!AD15/1000)/PP!$F$2 -> 3.2982826 | G10: =datos!MH15 -> 32.56 | H10: =datos!BK15/$H$2 -> 70.224592 | I10: =datos!NB15 -> 108.57 | J10: =datos!BR15/$J$2 -> 23.233333 | K10: =datos!NE15 -> 85.36 | L10: =datos!BO15*$L$2 -> 12.733636 | M10: =datos!NA15 -> 33.37 | N10: =datos!BS15*$N$2 -> 22.302 | P10: =(datos!AG15/1000)/$P$2 -> 14.126471 | Q10: =datos!MY15*$Q$2 -> 53.76 | R10: =datos!BN15 -> 4.121 | U10: =T10*S10 -> 0 | V10: =datos!NC15+U10 -> 16.07 | W10: =datos!AV15*W$4 -> 104.8 | X10: =W10*X$4 -> 8.384 | Y10: =Y11/(1+(datos!G16/datos!G15-1)) -> 4.0053591 | AC10: =datos!MJ15 -> 11.06 | AD10: =datos!BB15*AD$4 -> 195.5 | AE10: =AD10*AE$4 -> 15.64 | AF10: =Y10 -> 4.0053591 | AI10: =AVERAGE(datos!ML15,datos!MM15,datos!MN15,datos!MO15) -> 20.433333 | AK10: =A10 -> 42522 | AL10: =B10/C10 -> 0.16566265 | AM10: =D10/E10 -> 0.31163793 | AN10: =F10/G10 -> 0.10129861 | AO10: =H10/I10 -> 0.64681396 | AP10: =J10/K10 -> 0.27218057 | AQ10: =L10/M10 -> 0.38158934 | AS10: =P10/Q10 -> 0.26276917 | AX10: Jun-23 - Ago-23 | AY10: 1723.42 | AZ10: =AY10/AY9-1 -> 0.29999774
A11: 42552 | B11: =datos!R16/1000 -> 2.95 | C11: =datos!MA16 -> 16.81 | D11: =datos!AI16 -> 7.64 | E11: =datos!MP16 -> 25.75 | F11: =(datos!AD16/1000)/PP!$F$2 -> 3.2457093 | G11: =datos!MH16 -> 33.07 | H11: =datos!BK16/$H$2 -> 70.11343 | I11: =datos!NB16 -> 108.43 | J11: =datos!BR16/$J$2 -> 23.016667 | K11: =datos!NE16 -> 85.67 | L11: =datos!BO16*$L$2 -> 13.271667 | M11: =datos!NA16 -> 32.66 | N11: =datos!BS16*$N$2 -> 22.302 | P11: =(datos!AG16/1000)/$P$2 -> 14.126471 | Q11: =datos!MY16*$Q$2 -> 54.58 | R11: =datos!BN16 -> 4.1948463 | U11: =T11*S11 -> 0 | V11: =datos!NC16+U11 -> 16.53 | W11: =datos!AV16*W$4 -> 115.6 | X11: =W11*X$4 -> 9.248 | Y11: =Y12/(1+(datos!G17/datos!G16-1)) -> 4.1034859 | AC11: =datos!MJ16 -> 11.91 | AD11: =datos!BB16*AD$4 -> 225.86 | AE11: =AD11*AE$4 -> 18.0688 | AF11: =Y11 -> 4.1034859 | AI11: =AVERAGE(datos!ML16,datos!MM16,datos!MN16,datos!MO16) -> 23.346667 | AK11: =A11 -> 42552 | AL11: =B11/C11 -> 0.17549078 | AM11: =D11/E11 -> 0.29669903 | AN11: =F11/G11 -> 0.098146636 | AO11: =H11/I11 -> 0.64662391 | AP11: =J11/K11 -> 0.26866659 | AQ11: =L11/M11 -> 0.40635844 | AS11: =P11/Q11 -> 0.25882137 | AX11: Sep-23 - Dic-23 | AY11: 2361.09 | AZ11: =AY11/AY10-1 -> 0.37000267
A12: 42583 | B12: =datos!R17/1000 -> 3.35 | C12: =datos!MA17 -> 17.24 | D12: =datos!AI17 -> 7.69 | E12: =datos!MP17 -> 27.95 | F12: =(datos!AD17/1000)/PP!$F$2 -> 3.0106658 | G12: =datos!MH17 -> 33.96 | H12: =datos!BK17/$H$2 -> 70 | I12: =datos!NB17 -> 108.56 | J12: =datos!BR17/$J$2 -> 24.45 | K12: =datos!NE17 -> 88.81 | L12: =datos!BO17*$L$2 -> 14.91 | M12: =datos!NA17 -> 33.68 | N12: =datos!BS17*$N$2 -> 29.862 | P12: =(datos!AG17/1000)/$P$2 -> 14.126471 | Q12: =datos!MY17*$Q$2 -> 54.68 | R12: =datos!BN17 -> 4.2666879 | U12: =T12*S12 -> 0 | V12: =datos!NC17+U12 -> 16.84 | W12: =datos!AV17*W$4 -> 101.2 | X12: =W12*X$4 -> 8.096 | Y12: =Y13/(1+(datos!G18/datos!G17-1)) -> 4.148089 | AC12: =datos!MJ17 -> 11.67 | AD12: =datos!BB17*AD$4 -> 202.5775 | AE12: =AD12*AE$4 -> 16.2062 | AF12: =Y12 -> 4.148089 | AI12: =AVERAGE(datos!ML17,datos!MM17,datos!MN17,datos!MO17) -> 21.426667 | AK12: =A12 -> 42583 | AL12: =B12/C12 -> 0.19431555 | AM12: =D12/E12 -> 0.27513417 | AN12: =F12/G12 -> 0.088653291 | AO12: =H12/I12 -> 0.64480472 | AP12: =J12/K12 -> 0.27530683 | AQ12: =L12/M12 -> 0.44269596 | AS12: =P12/Q12 -> 0.25834804 | AX12: Ene-24 - Feb-24 | AY12: 4279.47 | AZ12: =AY12/AY11-1 -> 0.81249762
A13: 42614 | B13: =datos!R18/1000 -> 3.55 | C13: =datos!MA18 -> 18.18 | D13: =datos!AI18 -> 8.55 | E13: =datos!MP18 -> 29.03 | F13: =(datos!AD18/1000)/PP!$F$2 -> 2.7243953 | G13: =datos!MH18 -> 34.29 | H13: =datos!BK18/$H$2 -> 70.764519 | I13: =datos!NB18 -> 110.92 | J13: =datos!BR18/$J$2 -> 26.616667 | K13: =datos!NE18 -> 96.21 | L13: =datos!BO18*$L$2 -> 14.160682 | M13: =datos!NA18 -> 34.85 | N13: =datos!BS18*$N$2 -> 30.24 | P13: =(datos!AG18/1000)/$P$2 -> 14.126471 | Q13: =datos!MY18*$Q$2 -> 55.46 | R13: =datos!BN18 -> 4.3778386 | U13: =T13*S13 -> 0 | V13: =datos!NC18+U13 -> 17.03 | W13: =datos!AV18*W$4 -> 112.4 | X13: =W13*X$4 -> 8.992 | Y13: =Y14/(1+(datos!G19/datos!G18-1)) -> 4.1891239 | AC13: =datos!MJ18 -> 11.95 | AD13: =datos!BB18*AD$4 -> 251.7 | AE13: =AD13*AE$4 -> 20.136 | AF13: =Y13 -> 4.1891239 | AI13: =AVERAGE(datos!ML18,datos!MM18,datos!MN18,datos!MO18) -> 25.486667 | AK13: =A13 -> 42614 | AL13: =B13/C13 -> 0.19526953 | AM13: =D13/E13 -> 0.29452291 | AN13: =F13/G13 -> 0.079451599 | AO13: =H13/I13 -> 0.63797799 | AP13: =J13/K13 -> 0.27665177 | AQ13: =L13/M13 -> 0.40633233 | AS13: =P13/Q13 -> 0.25471458 | AX13: Mar-24 - Jun-24 | AY13: 5333.08 | AZ13: =AY13/AY12-1 -> 0.24620105
A14: 42644 | B14: =datos!R19/1000 -> 3.75 | C14: =datos!MA19 -> 18.49 | D14: =datos!AI19 -> 9.65 | E14: =datos!MP19 -> 30.03 | F14: =(datos!AD19/1000)/PP!$F$2 -> 2.7571119 | G14: =datos!MH19 -> 33.94 | H14: =datos!BK19/$H$2 -> 68.346189 | I14: =datos!NB19 -> 112.94 | J14: =datos!BR19/$J$2 -> 28.583333 | K14: =datos!NE19 -> 98.99 | L14: =datos!BO19*$L$2 -> 15.65375 | M14: =datos!NA19 -> 36.68 | N14: =datos!BS19*$N$2 -> 30.24 | P14: =(datos!AG19/1000)/$P$2 -> 15 | Q14: =datos!MY19*$Q$2 -> 56.26 | R14: =datos!BN19 -> 4.428 | U14: =T14*S14 -> 0 | V14: =datos!NC19+U14 -> 17.55 | W14: =datos!AV19*W$4 -> 95.2 | X14: =W14*X$4 -> 7.616 | Y14: =Y15/(1+(datos!G20/datos!G19-1)) -> 4.3015237 | AC14: =datos!MJ19 -> 12.55 | AD14: =datos!BB19*AD$4 -> 206.625 | AE14: =AD14*AE$4 -> 16.53 | AF14: =Y14 -> 4.3015237 | AI14: =AVERAGE(datos!ML19,datos!MM19,datos!MN19,datos!MO19) -> 25.193333 | AK14: =A14 -> 42644 | AL14: =B14/C14 -> 0.20281233 | AM14: =D14/E14 -> 0.32134532 | AN14: =F14/G14 -> 0.081234883 | AO14: =H14/I14 -> 0.60515485 | AP14: =J14/K14 -> 0.28874971 | AQ14: =L14/M14 -> 0.42676527 | AS14: =P14/Q14 -> 0.26661927 | AX14: Jul-24 - Dic-24 | AY14: 6239.7 | AZ14: =AY14/AY13-1 -> 0.16999932
